Workbook

Sheet 右膝関節角度
A1: 0 | B1: 5.91356 | C1: 4.99803 | D1: 5.48591 | E1: 10.2544 | F1: 2.868097 | G1: 1.1259795 | H1: 0.0991525 | I1: 7.41429 | J1: 0.6961979 | K1: 6.0314415 | L1: 5.33989 | M1: 4.78273 | N1: 3.305365 | O1: 4.390391 | P1: 4.4789596 | Q1: 0.73106701 | R1: 10.2544 | S1: 0.0991525 | T1: 2.7354023 | U1: 4.5692361 | V1: 2.8253062
A2: 0.01 | B2: 7.4140174 | C2: 6.0590241 | D2: 6.6676957 | E2: 11.734496 | F2: 3.9178974 | G2: 2.2489697 | H2: 1.0451813 | I2: 9.0069491 | J2: 2.2260029 | K2: 7.6379035 | L2: 7.0415917 | M2: 6.2501421 | N2: 5.1418642 | O2: 6.3394666 | P2: 5.9093715 | Q2: 0.76366832 | R2: 11.734496 | S2: 1.0451813 | T2: 2.8573852 | U2: 5.9684106 | V2: 2.9651598
A3: 0.02 | B3: 8.8358525 | C3: 7.1035701 | D3: 7.9760487 | E3: 13.042683 | F3: 4.8801354 | G3: 3.1940199 | H3: 2.0864955 | I3: 10.623229 | J3: 3.7533357 | K3: 9.4274176 | L3: 8.8463093 | M3: 7.8168861 | N3: 6.9248771 | O3: 8.3292758 | P3: 7.345724 | Q3: 0.80419917 | R3: 13.042683 | S3: 2.0864955 | T3: 3.0090378 | U3: 7.3780968 | V3: 3.1293672
A4: 0.03 | B4: 10.162799 | C4: 8.1308376 | D4: 9.493513 | E4: 14.162324 | F4: 5.7366946 | G4: 3.9243148 | H4: 3.3047682 | I4: 12.271004 | J4: 5.2770098 | K4: 11.422456 | L4: 10.917314 | M4: 9.3993739 | N4: 8.6410856 | O4: 10.363761 | P4: 8.8005182 | Q4: 0.85659582 | R4: 14.162324 | S4: 3.3047682 | T4: 3.2050881 | U4: 8.8127823 | V4: 3.3356195
A5: 0.04 | B5: 11.374612 | C5: 9.2512356 | D5: 11.550464 | E5: 15.558586 | F5: 6.7838406 | G5: 4.5477638 | H5: 4.8803124 | I5: 13.832073 | J5: 6.9878953 | K5: 13.694664 | L5: 13.03961 | M5: 10.718372 | N5: 10.433783 | O5: 12.62409 | P5: 10.37695 | Q5: 0.92070776 | R5: 15.558586 | S5: 4.5477638 | T5: 3.444973 | U5: 10.372578 | V5: 3.5856012
A6: 0.05 | B6: 12.591823 | C6: 10.470798 | D6: 13.828286 | E6: 17.333251 | F6: 8.0595748 | G6: 5.2210866 | H6: 6.6202439 | I6: 15.378655 | J6: 8.7618566 | K6: 15.907338 | L6: 15.204278 | M6: 11.652001 | N6: 12.179045 | O6: 14.787254 | P6: 11.999678 | Q6: 0.99519396 | R6: 17.333251 | S6: 5.2210866 | T6: 3.7236748 | U6: 11.98588 | V6: 3.8753511
A7: 0.06 | B7: 13.839888 | C7: 11.75896 | D7: 16.403903 | E7: 19.590261 | F7: 9.7076465 | G7: 6.0030179 | H7: 8.5743227 | I7: 16.925145 | J7: 10.604211 | K7: 18.02082 | L7: 16.612103 | M7: 12.354967 | N7: 13.799494 | O7: 16.807578 | P7: 13.643023 | Q7: 1.0634135 | R7: 19.590261 | S7: 6.0030179 | T7: 3.9789288 | U7: 13.630986 | V7: 4.1411352
A8: 0.07 | B8: 14.989625 | C8: 13.04395 | D8: 18.689498 | E8: 22.11438 | F8: 11.526924 | G8: 6.9855852 | H8: 10.290511 | I8: 18.403364 | J8: 12.28097 | K8: 19.578722 | L8: 17.670785 | M8: 12.852744 | N8: 15.254732 | O8: 18.553577 | P8: 15.159669 | Q8: 1.1254933 | R8: 22.11438 | S8: 6.9855852 | T8: 4.2112104 | U8: 15.152357 | V8: 4.3830743
A9: 0.08 | B9: 15.965749 | C9: 14.165635 | D9: 20.694426 | E9: 24.384248 | F9: 13.253778 | G9: 8.0043492 | H9: 11.649862 | I9: 19.775382 | J9: 13.845526 | K9: 20.86581 | L9: 17.54354 | M9: 13.17279 | N9: 16.621628 | O9: 20.180292 | P9: 16.437358 | Q9: 1.1818813 | R9: 24.384248 | S9: 8.0043492 | T9: 4.422195 | U9: 16.423184 | V9: 4.6024354
A10: 0.09 | B10: 16.524618 | C10: 14.984277 | D10: 21.855482 | E10: 26.203855 | F10: 14.615879 | G10: 8.9951791 | H10: 12.285836 | I10: 20.674055 | J10: 14.945494 | K10: 21.628258 | L10: 17.037086 | M10: 13.400836 | N10: 17.849782 | O10: 21.660788 | P10: 17.332959 | Q10: 1.2349069 | R10: 26.203855 | S10: 8.9951791 | T10: 4.6205986 | U10: 17.293203 | V10: 4.8067787
A11: 0.1 | B11: 16.450174 | C11: 15.300584 | D11: 22.750395 | E11: 26.942378 | F11: 15.373001 | G11: 9.7566874 | H11: 12.621758 | I11: 21.096 | J11: 15.871849 | K11: 22.082304 | L11: 16.093207 | M11: 13.535844 | N11: 18.869649 | O11: 22.661206 | P11: 17.814645 | Q11: 1.2673979 | R11: 26.942378 | S11: 9.7566874 | T11: 4.7421688 | U11: 17.733491 | V11: 4.9256767
A12: 0.11 | B12: 16.030044 | C12: 15.351933 | D12: 23.204444 | E12: 27.246333 | F12: 15.806 | G12: 10.352822 | H12: 12.427333 | I12: 21.1604 | J12: 16.557816 | K12: 22.330344 | L12: 15.196078 | M12: 13.499289 | N12: 19.737883 | O12: 23.306971 | P12: 18.014835 | Q12: 1.3007624 | R12: 27.246333 | S12: 10.352822 | T12: 4.8670072 | U12: 17.882293 | V12: 5.0393749
... A100: 0.99 | B100: 5.89525 | C100: 4.44438 | D100: 6.25564 | E100: 9.27854 | F100: -0.3408409 | G100: 2.781145 | H100: 2.50858 | I100: 8.32219 | J100: 1.8175134 | K100: 7.2159955 | L100: 5.997135 | M100: 6.62682 | N100: 3.79185 | O100: -2.0394 | P100: 4.4681999 | Q100: 0.86893215 | R100: 9.27854 | S100: -2.0394 | T100: 3.2512464 | U100: 4.5202268 | V100: 3.3779333

Sheet 左膝関節角度
A1: 0 | B1: 1.040151 | C1: 11.454595 | D1: 3.42727 | E1: 9.206465 | F1: 2.6181572 | G1: -1.31446 | H1: 4.46852 | I1: 6.96008 | J1: 4.305216 | K1: 16.66016 | L1: 5.90584 | M1: 5.220435 | N1: 1.4785545 | O1: 4.8743456 | P1: 5.4503807 | Q1: 1.2271376 | R1: 16.66016 | S1: -1.31446 | T1: 4.5915286 | U1: 5.7559058 | V1: 4.6285244
A2: 0.01 | B2: 2.5917676 | C2: 12.764409 | D2: 5.0560378 | E2: 11.665494 | F2: 3.584793 | G2: -0.34874525 | H2: 5.3642473 | I2: 8.3332 | J2: 6.2622913 | K2: 18.391353 | L2: 7.1639772 | M2: 6.6920533 | N2: 3.0949213 | O2: 7.0399387 | P2: 6.9754098 | Q2: 1.270976 | R2: 18.391353 | S2: -0.34874525 | T2: 4.7555569 | U2: 7.273909 | V2: 4.8112945
A3: 0.02 | B3: 4.257569 | C3: 14.073163 | D3: 6.8142746 | E3: 14.04829 | F3: 4.5208912 | G3: 0.65969909 | H3: 6.3393418 | I3: 9.6187473 | J3: 7.9330013 | K3: 20.081883 | L3: 8.3918329 | M3: 8.0794208 | N3: 4.7460117 | O3: 8.9721638 | P3: 8.4668778 | Q3: 1.315289 | R3: 20.081883 | S3: 0.65969909 | T3: 4.9213609 | U3: 8.7530983 | V3: 4.9995623
A4: 0.03 | B4: 6.0727835 | C4: 15.38382 | D4: 8.786417 | E4: 16.346861 | F4: 5.4180667 | G4: 1.7197136 | H4: 7.4618327 | I4: 10.787531 | J4: 9.2218909 | K4: 21.727814 | L4: 9.5466568 | M4: 9.3917086 | N4: 6.4460026 | O4: 10.661585 | P4: 9.9266202 | Q4: 1.3556952 | R4: 21.727814 | S4: 1.7197136 | T4: 5.0725471 | U4: 10.19436 | V4: 5.1756879
A5: 0.04 | B5: 8.1340991 | C5: 16.595425 | D5: 11.313273 | E5: 18.585379 | F5: 6.4234696 | G5: 2.9424563 | H5: 8.965043 | I5: 11.9427 | J5: 10.400132 | K5: 22.912973 | L5: 10.707051 | M5: 10.593097 | N5: 8.3005857 | O5: 12.405671 | P5: 11.444382 | Q5: 1.3609242 | R5: 22.912973 | S5: 2.9424563 | T5: 5.0921123 | U5: 11.686213 | V5: 5.2156908
A6: 0.05 | B6: 10.156116 | C6: 17.717686 | D6: 14.065181 | E6: 20.770557 | F6: 7.6133658 | G6: 4.3210202 | H6: 10.642155 | I6: 13.065073 | J6: 11.582378 | K6: 23.771812 | L6: 11.871378 | M6: 11.763272 | N6: 10.231251 | O6: 14.150688 | P6: 12.980138 | Q6: 1.3497944 | R6: 23.771812 | S6: 4.3210202 | T6: 5.0504682 | U6: 13.191591 | V6: 5.1917912
A7: 0.06 | B7: 11.998124 | C7: 18.578853 | D7: 17.109697 | E7: 22.852138 | F7: 9.0984141 | G7: 5.9473442 | H7: 12.523245 | I7: 14.111127 | J7: 12.820742 | K7: 24.228907 | L7: 13.088232 | M7: 12.864318 | N7: 12.17548 | O7: 15.942969 | P7: 14.524256 | Q7: 1.3165606 | R7: 24.228907 | S7: 5.9473442 | T7: 4.9261186 | U7: 14.704932 | V7: 5.0787569
A8: 0.07 | B8: 13.247745 | C8: 19.163782 | D8: 19.739126 | E8: 24.668429 | F8: 10.663626 | G8: 7.7144622 | H8: 14.1479 | I8: 15.122636 | J8: 14.302233 | K8: 24.241135 | L8: 14.290826 | M8: 13.846171 | N8: 14.008152 | O8: 17.522771 | P8: 15.905643 | Q8: 1.2678502 | R8: 24.668429 | S8: 7.7144622 | T8: 4.743861 | U8: 16.051603 | V8: 4.9047375
A9: 0.08 | B9: 14.120091 | C9: 19.525605 | D9: 21.966859 | E9: 26.276584 | F9: 12.168311 | G9: 9.4136818 | H9: 15.3879 | I9: 16.100718 | J9: 15.892632 | K9: 24.123019 | L9: 15.390365 | M9: 14.537344 | N9: 15.633321 | O9: 18.87217 | P9: 17.100614 | Q9: 1.2304574 | R9: 26.276584 | S9: 9.4136818 | T9: 4.6039502 | U9: 17.213483 | V9: 4.7717404
A10: 0.09 | B10: 14.348427 | C10: 19.624795 | D10: 22.9671 | E10: 27.581182 | F10: 13.459006 | G10: 10.835355 | H10: 15.8299 | I10: 16.961145 | J10: 17.552975 | K10: 23.868738 | L10: 16.264645 | M10: 14.89085 | N10: 16.923405 | O10: 19.951663 | P10: 17.932799 | Q10: 1.2007585 | R10: 27.581182 | S10: 10.835355 | T10: 4.4928268 | U10: 18.010445 | V10: 4.6664954
A11: 0.1 | B11: 14.251148 | C11: 19.51237 | D11: 23.591042 | E11: 28.467183 | F11: 14.374123 | G11: 11.795703 | H11: 15.9419 | I11: 17.557973 | J11: 18.934452 | K11: 23.464484 | L11: 16.880295 | M11: 14.968985 | N11: 17.730462 | O11: 20.49142 | P11: 18.425824 | Q11: 1.190969 | R11: 28.467183 | S11: 11.795703 | T11: 4.456198 | U11: 18.479314 | V11: 4.6334777
A12: 0.11 | B12: 13.986706 | C12: 19.262189 | D12: 23.604167 | E12: 29.150833 | F12: 15.036921 | G12: 12.509744 | H12: 15.4779 | I12: 17.9571 | J12: 20.10678 | K12: 22.961977 | L12: 16.921611 | M12: 14.777433 | N12: 18.312306 | O12: 20.668588 | P12: 18.623875 | Q12: 1.1977782 | R12: 29.150833 | S12: 12.509744 | T12: 4.4816755 | U12: 18.647842 | V12: 4.6637419
... A100: 0.99 | B100: 0.876401 | C100: 11.267345 | D100: 3.75654 | E100: 7.503535 | F100: 0.88112065 | G100: -1.70821 | H100: 5.86814 | I100: 8.5646 | J100: 4.267317 | K100: 14.96503 | L100: 6.841705 | M100: 4.342425 | N100: 2.30441 | O100: 4.1346246 | P100: 5.2760702 | Q100: 1.1723318 | R100: 14.96503 | S100: -1.70821 | T100: 4.3864639 | U100: 5.5046595 | V100: 4.4779441

Sheet 右足関節角度
A1: 0 | B1: 2.52527 | C1: -5.98687 | D1: 5.05621 | E1: 5.02921 | F1: -2.355228 | G1: 2.145985 | H1: 5.64678 | I1: 4.44857 | J1: 6.121953 | K1: -6.869195 | L1: -4.7953 | M1: -0.415076 | N1: 3.529955 | O1: -0.8682029 | P1: 0.94386151 | Q1: 1.2031998 | R1: 6.121953 | S1: -6.869195 | T1: 4.5019613 | U1: 0.74493124 | V1: 4.621302
A2: 0.01 | B2: 1.4468054 | C2: -7.0454939 | D2: 3.2291737 | E2: 2.397406 | F2: -3.6559983 | G2: 0.10003526 | H2: 3.1247861 | I2: 3.2058218 | J2: 5.1671342 | K2: -7.6116392 | L2: -5.5528517 | M2: -1.5239637 | N2: 2.4840035 | O2: -2.1765138 | P2: -0.45794961 | Q2: 1.1170252 | R2: 5.1671342 | S2: -7.6116392 | T2: 4.1795257 | U2: -0.6842537 | V2: 4.2599764
A3: 0.02 | B3: 0.27460333 | C3: -7.8874249 | D3: 1.6452754 | E3: -0.50041566 | F3: -4.9765471 | G3: -1.8847532 | H3: 0.83789455 | I3: 1.8753395 | J3: 4.1342217 | K3: -7.8994546 | L3: -5.7690421 | M3: -2.4299908 | N3: 1.3683798 | O3: -3.1320008 | P3: -1.7388511 | Q3: 1.0104205 | R3: 4.1342217 | S3: -7.8994546 | T3: 3.7806474 | U3: -1.9778688 | V3: 3.8233413
A4: 0.03 | B4: -1.01073 | C4: -8.3670274 | D4: 0.46308303 | E4: -3.6899985 | F4: -6.3209667 | G4: -3.7957263 | H4: -1.0123782 | I4: 0.42787818 | J4: 2.9857306 | K4: -7.6499298 | L4: -4.6888882 | M4: -3.132427 | N4: 0.17107317 | O4: -3.7005197 | P4: -2.8086305 | Q4: 0.88624603 | R4: 2.9857306 | S4: -8.3670274 | T4: 3.316029 | U4: -3.0378385 | V4: 3.3340044
A5: 0.04 | B5: -1.7794767 | C5: -8.090508 | D5: 0.1702877 | E5: -5.6024314 | F5: -6.9827883 | G5: -5.3455606 | H5: -1.8557285 | I5: -0.40443527 | J5: 1.892538 | K5: -6.5481541 | L5: -3.0468096 | M5: -3.5443593 | N5: -1.0601512 | O5: -3.852448 | P5: -3.2892875 | Q5: 0.79067295 | R5: 1.892538 | S5: -8.090508 | T5: 2.9584273 | U5: -3.4607595 | V5: 3.0059457
A6: 0.05 | B6: -2.0738857 | C6: -7.3456004 | D6: 0.25080007 | E6: -6.3856898 | F6: -7.1028217 | G6: -6.6199463 | H6: -2.2306397 | I6: -0.75509355 | J6: 0.89070431 | K6: -5.2281767 | L6: -1.0124669 | M6: -3.6528854 | N6: -2.1219066 | O6: -3.8118378 | P6: -3.371389 | Q6: 0.74612263 | R6: 0.89070431 | S6: -7.3456004 | T6: 2.7917352 | U6: -3.467503 | V6: 2.8815204
A7: 0.06 | B7: -1.6179988 | C7: -6.1485424 | D7: 0.88308848 | E7: -5.7584858 | F7: -6.3829348 | G7: -7.4699115 | H7: -1.9044336 | I7: -0.15792545 | J7: 0.1831997 | K7: -3.6304044 | L7: 0.69645433 | M7: -3.5452755 | N7: -2.8336189 | O7: -3.5434383 | P7: -2.9450162 | Q7: 0.74119309 | R7: 0.88308848 | S7: -7.4699115 | T7: 2.7732906 | U7: -2.9535852 | V7: 2.8863395
A8: 0.07 | B8: -0.63226396 | C8: -4.620012 | D8: 1.6188846 | E8: -3.9304708 | F8: -5.0571665 | G8: -7.4936073 | H8: -1.5191442 | I8: 0.96511491 | J8: -0.13108918 | K8: -2.1096727 | L8: 2.1938616 | M8: -3.209933 | N8: -2.9142722 | O8: -2.7767654 | P8: -2.1154669 | Q8: 0.73348931 | R8: 2.1938616 | S8: -7.4936073 | T8: 2.7444657 | U8: -2.0540203 | V8: 2.8464894
A9: 0.08 | B9: 0.42636998 | C9: -3.1494558 | D9: 2.4548496 | E9: -2.0508613 | F9: -3.6234249 | G9: -7.1225095 | H9: -1.0452296 | I9: 2.2798655 | J9: -0.18989911 | K9: -0.62698484 | L9: 2.9250246 | M9: -2.7445906 | N9: -2.7069157 | O9: -1.8150669 | P9: -1.2134878 | Q9: 0.730071 | R9: 2.9250246 | S9: -7.1225095 | T9: 2.7316755 | U9: -1.0986087 | V9: 2.8077983
A10: 0.09 | B10: 1.3485007 | C10: -1.7525506 | D10: 3.4759527 | E10: -0.28408655 | F10: -2.2777266 | G10: -6.1870914 | H10: -0.56114509 | I10: 3.4827836 | J10: 0.18635406 | K10: 0.69765271 | L10: 3.483565 | M10: -2.2054118 | N10: -2.1236245 | O10: -0.62240227 | P10: -0.23851643 | Q10: 0.72090779 | R10: 3.483565 | S10: -6.1870914 | T10: 2.6973899 | U10: -0.093508111 | V10: 2.7501496
A11: 0.1 | B11: 1.9028633 | C11: -0.64176119 | D11: 4.5787054 | E11: 0.94860226 | F11: -1.2016578 | G11: -5.1314087 | H11: -0.057738788 | I11: 4.4434291 | J11: 0.62247048 | K11: 1.9058777 | L11: 3.8549228 | M11: -1.5934128 | N11: -1.4813162 | O11: 0.47846767 | P11: 0.6162888 | Q11: 0.71076868 | R11: 4.5787054 | S11: -5.1314087 | T11: 2.6594529 | U11: 0.77764303 | V11: 2.6957769
A12: 0.11 | B12: 2.2808944 | C12: 0.35441806 | D12: 5.8435989 | E12: 2.0664033 | F12: -0.24669763 | G12: -4.0670322 | H12: 0.58905333 | I12: 5.22237 | J12: 1.1414745 | K12: 3.0228888 | L12: 4.2497644 | M12: -0.86864056 | N12: -0.80413089 | O12: 1.4799253 | P12: 1.4474493 | Q12: 0.70605168 | R12: 5.8435989 | S12: -4.0670322 | T12: 2.6418035 | U12: 1.6206477 | V12: 2.6656621
... A100: 0.99 | B100: 0.978606 | C100: -7.8244 | D100: 5.64219 | E100: 3.26834 | F100: -0.1511402 | G100: 2.71223 | H100: 4.56333 | I100: 6.0588 | J100: 7.2295185 | K100: -5.8534765 | L100: -3.87431 | M100: 3.02059 | N100: 4.35867 | O100: -2.038998 | P100: 1.2921393 | Q100: 1.2404614 | R100: 7.2295185 | S100: -7.8244 | T100: 4.6413814 | U100: 1.0562523 | V100: 4.7427534

Sheet 左足関節角度
A1: 0 | B1: -5.106285 | C1: -6.655835 | D1: -2.8826 | E1: 1.78303 | F1: -3.300012 | G1: -0.524808 | H1: 2.98443 | I1: 2.32412 | J1: 6.593767 | K1: -8.716153 | L1: -2.936725 | M1: 6.201635 | N1: 6.285205 | O1: -2.305624 | P1: -0.44684679 | Q1: 1.3174541 | R1: 6.593767 | S1: -8.716153 | T1: 4.9294619 | U1: -0.96469692 | V1: 4.717768
A2: 0.01 | B2: -6.8333379 | C2: -6.7730729 | D2: -4.6861112 | E2: 0.31075425 | F2: -4.8639058 | G2: -2.5043875 | H2: 0.98527182 | I2: 1.1448567 | J2: 5.8041931 | K2: -8.0256442 | L2: -3.422847 | M2: 5.0880605 | N2: 5.3367811 | O2: -4.1597018 | P2: -1.6142208 | Q2: 1.2663101 | R2: 5.8041931 | S2: -8.0256442 | T2: 4.7380986 | U2: -2.1489132 | V2: 4.4703788
A3: 0.02 | B3: -8.1114698 | C3: -6.6035821 | D3: -6.1111168 | E3: -1.0358732 | F3: -6.3509837 | G3: -4.7348134 | H3: -0.80571655 | I3: 0.17519964 | J3: 4.7713784 | K3: -7.0970363 | L3: -3.7324232 | M3: 3.8575406 | N3: 4.3746915 | O3: -5.5557689 | P3: -2.6399981 | Q3: 1.2081026 | R3: 4.7713784 | S3: -8.1114698 | T3: 4.5203059 | U3: -3.1795896 | V3: 4.2095152
A4: 0.03 | B4: -8.8137697 | C4: -6.0646506 | D4: -6.9107652 | E4: -2.2299893 | F4: -7.7624637 | G4: -7.2679852 | H4: -2.2101038 | I4: -0.51498255 | J4: 3.4142425 | K4: -5.9072875 | L4: -3.6162123 | M4: 2.6169509 | N4: 3.4189373 | O4: -6.523153 | P4: -3.455088 | Q4: 1.145981 | R4: 3.4189373 | S4: -8.8137697 | T4: 4.2878682 | U4: -3.9838592 | V4: 3.9594673
A5: 0.04 | B5: -8.5626729 | C5: -4.8685641 | D5: -6.3254929 | E5: -2.8642147 | F5: -8.1846848 | G5: -8.9495235 | H5: -2.6874879 | I5: -0.95567818 | J5: 1.8292867 | K5: -4.7907224 | L5: -3.1731704 | M5: 1.6472779 | N5: 2.7952205 | O5: -6.4791379 | P5: -3.6835403 | Q5: 1.046634 | R5: 2.7952205 | S5: -8.9495235 | T5: 3.9161459 | U5: -4.1819066 | V5: 3.5843112
A6: 0.05 | B6: -8.024678 | C6: -3.5096219 | D6: -5.1621451 | E6: -3.0806786 | F6: -8.0880427 | G6: -9.954371 | H6: -2.7338039 | I6: -1.2344436 | J6: 0.37867683 | K6: -3.7630954 | L6: -2.4994242 | M6: 1.1251827 | N6: 2.4133699 | O6: -5.9695983 | P6: -3.5787624 | Q6: 0.96740003 | R6: 2.4133699 | S6: -9.954371 | T6: 3.6196795 | U6: -4.0396956 | V6: 3.3123432
A7: 0.06 | B7: -7.1621086 | C7: -2.051267 | D7: -3.1609261 | E7: -2.7491853 | F7: -7.2593043 | G7: -9.9099912 | H7: -2.1382827 | I7: -1.2123364 | J7: -0.64114293 | K7: -2.8483143 | L7: -1.4113265 | M7: 0.83946559 | N7: 2.3153289 | O7: -4.9043991 | P7: -3.020985 | Q7: 0.8859895 | R7: 2.3153289 | S7: -9.9099912 | T7: 3.3150691 | U7: -3.4314707 | V7: 3.0577655
A8: 0.07 | B8: -6.2251653 | C8: -0.69566321 | D8: -1.2238558 | E8: -1.7381644 | F8: -5.9614499 | G8: -9.1503488 | H8: -1.5106064 | I8: -0.72381273 | J8: -0.89686227 | K8: -1.9589998 | L8: -0.23432454 | M8: 0.74900467 | N8: 2.3846947 | O8: -3.3756729 | P8: -2.1829448 | Q8: 0.8169082 | R8: 2.3846947 | S8: -9.1503488 | T8: 3.0565906 | U8: -2.5343016 | V8: 2.8720999
A9: 0.08 | B9: -5.2700094 | C9: 0.55195676 | D9: 0.65113511 | E9: -0.53121509 | F9: -4.5566969 | G9: -8.1855481 | H9: -0.83469727 | I9: 0.012629091 | J9: -0.76343189 | K9: -1.1098742 | L9: 1.096433 | M9: 0.75096615 | N9: 2.4453368 | O9: -1.7698093 | P9: -1.2509161 | Q9: 0.77044647 | R9: 2.4453368 | S9: -8.1855481 | T9: 2.8827467 | U9: -1.5352432 | V9: 2.7886637
A10: 0.09 | B10: -4.2877818 | C10: 1.5918885 | D10: 2.1704918 | E10: 0.90295377 | F10: -3.1605682 | G10: -7.1098891 | H10: -0.18157545 | I10: 1.1171807 | J10: -0.12894413 | K10: -0.32090745 | L10: 2.3565105 | M10: 0.77601309 | N10: 2.4884645 | O10: -0.18755232 | P10: -0.28383682 | Q10: 0.73991761 | R10: 2.4884645 | S10: -7.1098891 | T10: 2.7685182 | U10: -0.49709078 | V10: 2.7592896
A11: 0.1 | B11: -3.3383254 | C11: 2.5462653 | D11: 3.6191188 | E11: 2.2858405 | F11: -1.8678707 | G11: -6.0238499 | H11: 0.47675448 | I11: 2.1384509 | J11: 0.52359549 | K11: 0.34502608 | L11: 3.5354366 | M11: 0.85249803 | N11: 2.4880933 | O11: 1.0591882 | P11: 0.61715869 | Q11: 0.72675066 | R11: 3.6191188 | S11: -6.0238499 | T11: 2.719252 | U11: 0.47324064 | V11: 2.7742364
A12: 0.11 | B12: -2.424605 | C12: 3.3853433 | D12: 4.9984767 | E12: 3.6474667 | F12: -0.69036732 | G12: -4.9044878 | H12: 1.2503193 | I12: 3.09726 | J12: 1.189674 | K12: 0.95315622 | L12: 4.4121872 | M12: 1.02917 | N12: 2.5065428 | O12: 2.0934356 | P12: 1.467398 | Q12: 0.72128174 | R12: 4.9984767 | S12: -4.9044878 | T12: 2.6987892 | U12: 1.3874638 | V12: 2.7916861
... A100: 0.99 | B100: -5.73845 | C100: -6.384825 | D100: -0.439636 | E100: 2.62913 | F100: -2.8904305 | G100: 1.48927 | H100: 3.57887 | I100: 1.57693 | J100: 4.430237 | K100: -9.873219 | L100: -1.542355 | M100: 4.394115 | N100: 6.26985 | O100: -4.358627 | P100: -0.48993861 | Q100: 1.2847619 | R100: 6.26985 | S100: -9.873219 | T100: 4.8071388 | U100: -1.0099223 | V100: 4.5753129

Sheet 右股関節伸展角度
A1: 0 | B1: 31.9821 | C1: 23.07035 | D1: 36.1769 | E1: 27.4424 | F1: 21.99163 | G1: 24.6752 | H1: 21.4584 | I1: 24.6679 | J1: 22.0184 | K1: 31.25834 | L1: 29.1015 | M1: 25.7829 | N1: 25.47575 | O1: 24.66229 | P1: 26.411719 | Q1: 1.1557353 | R1: 36.1769 | S1: 21.4584 | T1: 4.3243655 | U1: 26.483716 | V1: 4.4922002
A2: 0.01 | B2: 31.769478 | C2: 22.636721 | D2: 35.865677 | E2: 27.663925 | F2: 21.677002 | G2: 24.475475 | H2: 21.071188 | I2: 24.398782 | J2: 21.752126 | K2: 30.992366 | L2: 28.986099 | M2: 25.651314 | N2: 25.468179 | O2: 24.635935 | P2: 26.217448 | Q2: 1.1627374 | R2: 35.865677 | S2: 21.071188 | T2: 4.3505648 | U2: 26.275084 | V2: 4.5226449
A3: 0.02 | B3: 31.564501 | C3: 22.160312 | D3: 35.582123 | E3: 27.778297 | F3: 21.277548 | G3: 24.154111 | H3: 20.705167 | I3: 24.122245 | J3: 21.499129 | K3: 30.800814 | L3: 28.834499 | M3: 25.516457 | N3: 25.396345 | O3: 24.526739 | P3: 25.994163 | Q3: 1.1768478 | R3: 35.582123 | S3: 20.705167 | T3: 4.4033611 | U3: 26.040149 | V3: 4.5796632
A4: 0.03 | B4: 31.368752 | C4: 21.643742 | D4: 35.344285 | E4: 27.775145 | F4: 20.775717 | G4: 23.685941 | H4: 20.3785 | I4: 23.835818 | J4: 21.265784 | K4: 30.689928 | L4: 28.609748 | M4: 25.341818 | N4: 25.243318 | O4: 24.326683 | P4: 25.734656 | Q4: 1.1980738 | R4: 35.344285 | S4: 20.3785 | T4: 4.4827816 | U4: 25.772451 | V4: 4.6635047
A5: 0.04 | B5: 31.043762 | C5: 21.170116 | D5: 35.299414 | E5: 27.645552 | F5: 20.332887 | G5: 23.091929 | H5: 20.184918 | I5: 23.466482 | J5: 21.099968 | K5: 30.669022 | L5: 28.309317 | M5: 24.986091 | N5: 25.000909 | O5: 24.025367 | P5: 25.451838 | Q5: 1.2216518 | R5: 35.299414 | S5: 20.184918 | T5: 4.5710026 | U5: 25.486525 | V5: 4.7557322
A6: 0.05 | B6: 30.643279 | C6: 20.759906 | D6: 35.326138 | E6: 27.483367 | F6: 19.984126 | G6: 22.511 | H6: 20.050691 | I6: 23.055382 | J6: 20.953464 | K6: 30.598019 | L6: 27.962746 | M6: 24.370449 | N6: 24.721164 | O6: 23.6758 | P6: 25.149681 | Q6: 1.2418008 | R6: 35.326138 | S6: 19.984126 | T6: 4.6463933 | U6: 25.182644 | V6: 4.8344154
A7: 0.06 | B7: 30.132055 | C7: 20.401027 | D7: 35.410306 | E7: 27.2862 | F7: 19.792172 | G7: 21.9766 | H7: 19.960509 | I7: 22.574418 | J7: 20.818654 | K7: 30.447378 | L7: 27.337848 | M7: 23.595439 | N7: 24.388947 | O7: 23.268946 | P7: 24.813607 | Q7: 1.2538107 | R7: 35.410306 | S7: 19.792172 | T7: 4.6913301 | U7: 24.846273 | V7: 4.8812336
A8: 0.07 | B8: 29.504802 | C8: 20.032998 | D8: 35.317054 | E8: 26.972404 | F8: 19.649023 | G8: 21.60122 | H8: 19.762933 | I8: 22.024682 | J8: 20.627563 | K8: 30.001796 | L8: 26.593063 | M8: 22.674763 | N8: 24.018542 | O8: 22.799826 | P8: 24.398619 | Q8: 1.2504547 | R8: 35.317054 | S8: 19.649023 | T8: 4.678773 | U8: 24.427856 | V8: 4.86849
A9: 0.08 | B9: 28.79512 | C9: 19.578294 | D9: 35.052104 | E9: 26.554399 | F9: 19.455105 | G9: 21.274068 | H9: 19.404267 | I9: 21.423409 | J9: 20.398424 | K9: 29.420017 | L9: 25.424929 | M9: 21.684227 | N9: 23.621877 | O9: 22.286687 | P9: 23.883781 | Q9: 1.2396726 | R9: 35.052104 | S9: 19.404267 | T9: 4.6384303 | U9: 23.903927 | V9: 4.8271937
A10: 0.09 | B10: 27.931573 | C10: 18.973018 | D10: 34.300282 | E10: 25.988636 | F10: 19.089685 | G10: 20.978795 | H10: 18.719418 | I10: 20.677973 | J10: 20.016774 | K10: 28.58292 | L10: 24.110968 | M10: 20.667845 | N10: 23.169218 | O10: 21.713249 | P10: 23.208597 | Q10: 1.2136435 | R10: 34.300282 | S10: 18.719418 | T10: 4.5410381 | U10: 23.211626 | V10: 4.7264475
A11: 0.1 | B11: 26.852476 | C11: 18.118525 | D11: 33.39489 | E11: 25.1263 | F11: 18.436476 | G11: 20.562924 | H11: 17.899764 | I11: 19.8033 | J11: 19.569503 | K11: 27.642148 | L11: 22.62202 | M11: 19.624365 | N11: 22.635857 | O11: 20.98141 | P11: 22.376426 | Q11: 1.1903014 | R11: 33.39489 | S11: 17.899764 | T11: 4.4536998 | U11: 22.356469 | V11: 4.6349062
A12: 0.11 | B12: 25.654133 | C12: 17.15205 | D12: 32.235089 | E12: 24.135144 | F12: 17.63147 | G12: 20.051422 | H12: 16.8454 | I12: 18.8317 | J12: 19.031374 | K12: 26.636109 | L12: 21.154272 | M12: 18.511011 | N12: 22.0436 | O12: 20.12847 | P12: 21.431518 | Q12: 1.166932 | R12: 32.235089 | S12: 16.8454 | T12: 4.3662596 | U12: 21.384434 | V12: 4.5408464
... A100: 0.99 | B100: 31.3376 | C100: 22.22495 | D100: 36.511 | E100: 26.8498 | F100: 21.14725 | G100: 24.2539 | H100: 20.7199 | I100: 25.0378 | J100: 21.87474 | K100: 32.893735 | L100: 28.91545 | M100: 25.9107 | N100: 25.73755 | O100: 24.24166 | P100: 26.261145 | Q100: 1.2505002 | R100: 36.511 | S100: 20.7199 | T100: 4.6789434 | U100: 26.301422 | V100: 4.867472

Sheet 左股関節伸展角度
A1: 0 | B1: 31.45555 | C1: 24.6711 | D1: 35.5764 | E1: 26.3534 | F1: 20.33605 | G1: 25.6412 | H1: 23.6657 | I1: 27.2923 | J1: 23.9962 | K1: 32.10168 | L1: 27.8925 | M1: 24.0993 | N1: 22.47145 | O1: 23.81627 | P1: 26.383507 | Q1: 1.1150557 | R1: 35.5764 | S1: 20.33605 | T1: 4.1721566 | U1: 26.684435 | V1: 4.1813887
A2: 0.01 | B2: 31.110776 | C2: 24.25829 | D2: 35.599629 | E2: 26.563584 | F2: 19.967938 | G2: 25.253968 | H2: 23.19267 | I2: 26.823936 | J2: 24.039333 | K2: 31.786509 | L2: 27.503988 | M2: 23.820912 | N2: 22.423371 | O2: 23.756572 | P2: 26.150105 | Q2: 1.1216513 | R2: 35.599629 | S2: 19.967938 | T2: 4.196835 | U2: 26.436777 | V2: 4.2231269
A3: 0.02 | B3: 30.820055 | C3: 23.810435 | D3: 35.624694 | E3: 26.701618 | F3: 19.543787 | G3: 24.816088 | H3: 22.734064 | I3: 26.374364 | J3: 24.022719 | K3: 31.43487 | L3: 27.07307 | M3: 23.425805 | N3: 22.322655 | O3: 23.549436 | P3: 25.875261 | Q3: 1.1377167 | R3: 35.624694 | S3: 19.543787 | T3: 4.2569461 | U3: 26.148539 | V3: 4.3010542
A4: 0.03 | B4: 30.601808 | C4: 23.315803 | D4: 35.652791 | E4: 26.759577 | F4: 19.053405 | G4: 24.317082 | H4: 22.302245 | I4: 25.949845 | J4: 23.926444 | K4: 31.043235 | L4: 26.53988 | M4: 22.947277 | N4: 22.162782 | O4: 23.188815 | P4: 25.554356 | Q4: 1.162815 | R4: 35.652791 | S4: 19.053405 | T4: 4.3508554 | U4: 25.815247 | V4: 4.4130643
A5: 0.04 | B5: 30.478283 | C5: 22.752649 | D5: 35.760714 | E5: 26.759764 | F5: 18.590835 | G5: 23.848892 | H5: 21.991421 | I5: 25.5166 | J5: 23.767692 | K5: 30.441082 | L5: 26.002535 | M5: 22.44062 | N5: 22.036077 | O5: 22.733544 | P5: 25.222908 | Q5: 1.1896492 | R5: 35.760714 | S5: 18.590835 | T5: 4.4512598 | U5: 25.468049 | V5: 4.5335892
A6: 0.05 | B6: 30.324553 | C6: 22.140765 | D6: 35.894425 | E6: 26.73881 | F6: 18.192398 | G6: 23.435233 | H6: 21.733815 | I6: 25.055627 | J6: 23.581276 | K6: 29.686195 | L6: 25.462256 | M6: 21.985959 | N6: 21.962107 | O6: 22.238635 | P6: 24.888004 | Q6: 1.2126864 | R6: 35.894425 | S6: 18.192398 | T6: 4.5374569 | U6: 25.113073 | V6: 4.6406832
A7: 0.06 | B7: 30.068014 | C7: 21.428658 | D7: 36.02653 | E7: 26.680052 | F7: 17.904418 | G7: 23.1131 | H7: 21.502118 | I7: 24.528973 | J7: 23.351734 | K7: 28.74294 | L7: 25.005535 | M7: 21.531791 | N7: 21.938298 | O7: 21.717018 | P7: 24.538513 | Q7: 1.2295273 | R7: 36.02653 | S7: 17.904418 | T7: 4.6004698 | U7: 24.738529 | V7: 4.724537
A8: 0.07 | B8: 29.516207 | C8: 20.611252 | D8: 35.945142 | E8: 26.490825 | F8: 17.647648 | G8: 22.818227 | H8: 21.154203 | I8: 23.947091 | J8: 23.098305 | K8: 27.606641 | L8: 24.55451 | M8: 21.047618 | N8: 21.908887 | O8: 21.052746 | P8: 24.09995 | Q8: 1.2323864 | R8: 35.945142 | S8: 17.647648 | T8: 4.6111677 | U8: 24.268493 | V8: 4.7543596
A9: 0.08 | B9: 28.781172 | C9: 19.716217 | D9: 35.657148 | E9: 26.206573 | F9: 17.365724 | G9: 22.490872 | H9: 20.631961 | I9: 23.329927 | J9: 22.826521 | K9: 26.445762 | L9: 24.075775 | M9: 20.455814 | N9: 21.808828 | O9: 20.283226 | P9: 23.576823 | Q9: 1.231649 | R9: 35.657148 | S9: 17.365724 | T9: 4.6084086 | U9: 23.712822 | V9: 4.7672523
A10: 0.09 | B10: 27.745218 | C10: 18.744241 | D10: 34.770682 | E10: 25.784732 | F10: 16.994169 | G10: 22.056318 | H10: 19.755991 | I10: 22.633618 | J10: 22.501937 | K10: 25.276964 | L10: 23.490745 | M10: 19.72565 | N10: 21.5878 | O10: 19.409244 | P10: 22.891236 | Q10: 1.2081856 | R10: 34.770682 | S10: 16.994169 | T10: 4.5206168 | U10: 22.991501 | V10: 4.6889769
A11: 0.1 | B11: 26.59176 | C11: 17.706695 | D11: 33.697043 | E11: 25.198348 | F11: 16.456142 | G11: 21.449753 | H11: 18.733785 | I11: 21.812436 | J11: 22.103914 | K11: 24.143949 | L11: 22.783673 | M11: 18.886792 | N11: 21.173085 | O11: 18.37553 | P11: 22.079493 | Q11: 1.1882046 | R11: 33.697043 | S11: 16.456142 | T11: 4.4458544 | U11: 22.149217 | V11: 4.6194183
A12: 0.11 | B12: 25.388844 | C12: 16.652906 | D12: 32.315178 | E12: 24.54235 | F12: 15.817338 | G12: 20.751367 | H12: 17.456633 | I12: 20.8976 | J12: 21.65081 | K12: 23.010502 | L12: 21.796244 | M12: 17.951517 | N12: 20.673533 | O12: 17.242971 | P12: 21.153414 | Q12: 1.1638174 | R12: 32.315178 | S12: 15.817338 | T12: 4.3546058 | U12: 21.190328 | V12: 4.530137
... A100: 0.99 | B100: 30.9978 | C100: 24.19475 | D100: 35.4022 | E100: 26.27705 | F100: 20.581825 | G100: 24.7723 | H100: 23.3135 | I100: 25.3028 | J100: 25.13218 | K100: 30.89532 | L100: 28.34605 | M100: 22.90125 | N100: 22.7123 | O100: 23.08396 | P100: 25.993806 | Q100: 1.0854115 | R100: 35.4022 | S100: 20.581825 | T100: 4.0612378 | U100: 26.24623 | V100: 4.1111725

Sheet 右股関節内旋角度
A1: 0 | B1: 2.43281 | C1: 2.51898 | D1: 4.91399 | E1: 10.5185 | F1: 3.015592 | G1: 12.1382 | H1: 3.13217 | I1: -2.94815 | J1: -1.952549 | K1: 8.1805425 | L1: -7.274785 | M1: 4.31343 | N1: 9.299735 | O1: 5.678842 | P1: 3.8548077 | Q1: 1.4353166 | R1: 12.1382 | S1: -7.274785 | T1: 5.3704631 | U1: 3.4359671 | V1: 5.3464675
A2: 0.01 | B2: 2.335168 | C2: 2.380184 | D2: 3.8076225 | E2: 10.6095 | F2: 2.6923235 | G2: 11.690653 | H2: 2.3930548 | I2: -3.5397964 | J2: -2.5893172 | K2: 8.2778387 | L2: -6.6988033 | M2: 4.4236128 | N2: 9.5095823 | O2: 6.2121283 | P2: 3.6788393 | Q2: 1.4441484 | R2: 11.690653 | S2: -6.6988033 | T2: 5.4035085 | U2: 3.2303206 | V2: 5.3460265
A3: 0.02 | B3: 2.3655859 | C3: 2.3829757 | D3: 2.7317219 | E3: 10.693079 | F3: 2.3820959 | G3: 11.132829 | H3: 1.7662048 | I3: -4.1645873 | J3: -3.1032892 | K3: 8.2718439 | L3: -5.9763032 | M3: 4.8059445 | N3: 9.5767355 | O3: 6.5332981 | P3: 3.5284382 | Q3: 1.4451948 | R3: 11.132829 | S3: -5.9763032 | T3: 5.4074239 | U3: 3.0631845 | V3: 5.3285953
A4: 0.03 | B4: 2.5505588 | C4: 2.5713235 | D4: 1.7061579 | E4: 10.768518 | F4: 2.0876073 | G4: 10.441913 | H4: 1.3478473 | I4: -4.8335709 | J4: -3.4355227 | K4: 8.1444268 | L4: -4.8729823 | M4: 5.3093136 | N4: 9.4585982 | O4: 6.6218242 | P4: 3.4190009 | Q4: 1.4263797 | R4: 10.768518 | S4: -4.8729823 | T4: 5.3370241 | U4: 2.9544165 | V4: 5.2520401
A5: 0.04 | B5: 2.5458717 | C5: 3.0142335 | D5: 0.83618396 | E5: 10.692778 | F5: 1.8981151 | G5: 9.753183 | H5: 1.4456273 | I5: -5.44202 | J5: -3.502802 | K5: 7.8263605 | L5: -3.5876118 | M5: 5.4673015 | N5: 9.1454679 | O5: 6.4957363 | P5: 3.3277446 | Q5: 1.3830177 | R5: 10.692778 | S5: -5.44202 | T5: 5.1747782 | U5: 2.8802275 | V5: 5.0963128
A6: 0.05 | B6: 2.3642354 | C6: 3.6342625 | D6: 0.02752098 | E6: 10.549593 | F6: 1.8117816 | G6: 9.1579937 | H6: 1.7802212 | I6: -6.0343636 | J6: -3.4836587 | K6: 7.4248576 | L6: -2.1596368 | M6: 4.9414234 | N6: 8.756596 | O6: 6.3380846 | P6: 3.2220651 | Q6: 1.3356437 | R6: 10.549593 | S6: -6.0343636 | T6: 4.997521 | U6: 2.7963319 | V6: 4.9302682
A7: 0.06 | B7: 1.9021424 | C7: 4.410473 | D7: -0.71108242 | E7: 10.326952 | F7: 1.8899773 | G7: 8.7291485 | H7: 2.4114455 | I7: -6.6116664 | J7: -3.3784507 | K7: 6.9113359 | L7: -1.0072095 | M7: 4.0580903 | N7: 8.2761552 | O7: 6.1524459 | P7: 3.0971255 | Q7: 1.3013962 | R7: 10.326952 | S7: -6.6116664 | T7: 4.8693786 | U7: 2.6987386 | V7: 4.8248956
A8: 0.07 | B8: 1.2701256 | C8: 5.2702444 | D8: -1.4264117 | E8: 9.9648019 | F8: 2.0569586 | G8: 8.6292768 | H8: 2.8647279 | I8: -7.1321736 | J8: -3.3557873 | K8: 6.198773 | L8: 0.025926061 | M8: 2.910062 | N8: 7.6700351 | O8: 6.0184215 | P8: 2.92607 | Q8: 1.2877921 | R8: 9.9648019 | S8: -7.1321736 | T8: 4.8184769 | U8: 2.5611496 | V8: 4.8096602
A9: 0.08 | B9: 0.59536192 | C9: 5.9448306 | D9: -2.1192177 | E9: 9.4564272 | F9: 2.1817158 | G9: 8.6587673 | H9: 3.0510976 | I9: -7.5740673 | J9: -3.3885052 | K9: 5.3883086 | L9: 0.53988621 | M9: 1.9462726 | N9: 7.0027335 | O9: 5.8742939 | P9: 2.6827075 | Q9: 1.2911457 | R9: 9.4564272 | S9: -7.5740673 | T9: 4.8310248 | U9: 2.3503978 | V9: 4.8588939
A10: 0.09 | B10: -0.089171091 | C10: 6.2955332 | D10: -2.8131855 | E10: 8.7367918 | F10: 2.13309 | G10: 8.8360182 | H10: 2.4968855 | I10: -7.6805882 | J10: -3.6193409 | K10: 4.3813876 | L10: 0.93550382 | M10: 1.2190067 | N10: 6.2368527 | O10: 5.7056032 | P10: 2.3410276 | Q10: 1.2862806 | R10: 8.8360182 | S10: -7.6805882 | T10: 4.8128212 | U10: 2.0413488 | V10: 4.8714925
A11: 0.1 | B11: -0.81911725 | C11: 5.9172416 | D11: -3.4923075 | E11: 7.4078369 | F11: 1.712768 | G11: 8.9336333 | H11: 1.6545133 | I11: -7.4132364 | J11: -3.8673825 | K11: 3.4024629 | L11: 1.1424317 | M11: 0.72157103 | N11: 5.4777873 | O11: 5.3947776 | P11: 1.8694986 | Q11: 1.2441787 | R11: 8.9336333 | S11: -7.4132364 | T11: 4.6552904 | U11: 1.5919379 | V11: 4.7232687
A12: 0.11 | B12: -1.5688478 | C12: 5.2156761 | D12: -4.1292522 | E12: 5.8683667 | F12: 1.1075219 | G12: 8.9434817 | H12: 0.44044667 | I12: -6.86548 | J12: -4.1392478 | K12: 2.4497651 | L12: 1.2239788 | M12: 0.40262133 | N12: 4.7175017 | O12: 4.9642968 | P12: 1.3307735 | Q12: 1.1873761 | R12: 8.9434817 | S12: -6.86548 | T12: 4.4427546 | U12: 1.0702559 | V12: 4.5114914
... A100: 0.99 | B100: 1.53484 | C100: 3.347225 | D100: 3.88807 | E100: 11.0026 | F100: 3.12623 | G100: 13.2312 | H100: 1.20145 | I100: -3.39637 | J100: -3.091645 | K100: 9.401331 | L100: -7.114795 | M100: 3.65292 | N100: 9.71397 | O100: 3.612608 | P100: 3.5792596 | Q100: 1.5504606 | R100: 13.2312 | S100: -7.114795 | T100: 5.8012924 | U100: 3.1073588 | V100: 5.7517046

Sheet 左股関節内旋角度
A1: 0 | B1: -3.80304 | C1: 9.78643 | D1: 3.78112 | E1: 4.347795 | F1: 9.207159 | G1: 8.22879 | H1: 0.409673 | I1: 3.60651 | J1: -3.308252 | K1: 0.0277448 | L1: -5.244285 | M1: 4.81606 | N1: 1.0178415 | O1: 7.552617 | P1: 2.8875831 | Q1: 1.3094823 | R1: 9.78643 | S1: -5.244285 | T1: 4.8996342 | U1: 3.0314094 | V1: 5.0688473
A2: 0.01 | B2: -2.8670799 | C2: 9.9978689 | D2: 2.6120827 | E2: 4.9240734 | F2: 8.705773 | G2: 8.2091181 | H2: 0.13277227 | I2: 3.3573227 | J2: -3.5788357 | K2: 0.32087392 | L2: -5.5816429 | M2: 4.3491859 | N2: 1.1683991 | O2: 7.6255548 | P2: 2.8125333 | Q2: 1.2955269 | R2: 9.9978689 | S2: -5.5816429 | T2: 4.8474177 | U2: 2.9390052 | V2: 5.0212536
A3: 0.02 | B3: -1.6946397 | C3: 10.275697 | D3: 1.545678 | E3: 5.7485026 | F3: 8.2022656 | G3: 8.0949442 | H3: -0.024730939 | I3: 2.9050027 | J3: -3.6387085 | K3: 0.75044149 | L3: -5.4890699 | M3: 3.8910261 | N3: 1.396582 | O3: 7.4927451 | P3: 2.8182668 | Q3: 1.2647141 | R3: 10.275697 | S3: -5.4890699 | T3: 4.7321267 | U3: 2.9276272 | V3: 4.9069053
A4: 0.03 | B4: -0.21233712 | C4: 10.631158 | D4: 0.64883994 | E4: 6.8687064 | F4: 7.6981401 | G4: 7.8667164 | H4: 0.039504091 | I4: 2.1818391 | J4: -3.4176332 | K4: 1.3296512 | L4: -4.3596048 | M4: 3.4232327 | N4: 1.726311 | O4: 7.1589195 | P4: 2.9702459 | Q4: 1.1985921 | R4: 10.631158 | S4: -4.3596048 | T4: 4.4847209 | U4: 3.0659332 | V4: 4.6529469
A5: 0.04 | B5: 1.6539355 | C5: 11.110677 | D5: 0.19533728 | E5: 8.1370894 | F5: 7.1780361 | G5: 7.6890715 | H5: 0.59201144 | I5: 1.2531155 | J5: -2.9784399 | K5: 1.6866962 | L5: -2.8930982 | M5: 2.8624203 | N5: 2.0674357 | O5: 6.6734969 | P5: 3.2305561 | Q5: 1.1386765 | R5: 11.110677 | S5: -2.9784399 | T5: 4.2605372 | U5: 3.3200269 | V5: 4.4207973
A6: 0.05 | B6: 3.4849468 | C6: 11.570276 | D6: -0.078283103 | E6: 9.2509348 | F6: 6.6398663 | G6: 7.5764269 | H6: 1.3703136 | I6: 0.33348564 | J6: -2.4986524 | K6: 1.8055543 | L6: -1.1886797 | M6: 2.1709412 | N6: 2.3440703 | O6: 6.2656962 | P6: 3.5033498 | Q6: 1.1084974 | R6: 11.570276 | S6: -2.4986524 | T6: 4.1476176 | U6: 3.5925251 | V6: 4.3029855
A7: 0.06 | B7: 5.0757605 | C7: 11.814041 | D7: -0.11793236 | E7: 10.071722 | F7: 6.0778318 | G7: 7.5703242 | H7: 2.4627864 | I7: -0.47775964 | J7: -2.0082616 | K7: 1.6238708 | L7: 0.022078339 | M7: 1.3943564 | N7: 2.4537953 | O7: 5.9619552 | P7: 3.7088977 | Q7: 1.1117003 | R7: 11.814041 | S7: -2.0082616 | T7: 4.1596016 | U7: 3.8054441 | V7: 4.313093
A8: 0.07 | B8: 5.8839958 | C8: 11.783646 | D8: -0.22267229 | E8: 10.230761 | F8: 5.4913698 | G8: 7.6059424 | H8: 3.3586336 | I8: -1.0850104 | J8: -1.5009873 | K8: 1.2415394 | L8: 0.99966808 | M8: 0.53986973 | N8: 2.2192157 | O8: 5.8832776 | P8: 3.7449464 | Q8: 1.1166455 | R8: 11.783646 | S8: -1.5009873 | T8: 4.1781048 | U8: 3.8623103 | V8: 4.3246228
A9: 0.08 | B9: 6.227069 | C9: 11.495938 | D9: -0.39040319 | E9: 10.079174 | F9: 4.8749538 | G9: 7.6452831 | H9: 3.9595427 | I9: -1.5895145 | J9: -0.98433498 | K9: 0.89902438 | L9: 1.1832849 | M9: -0.33682491 | N9: 1.7739015 | O9: 5.7921922 | P9: 3.6163776 | Q9: 1.1241299 | R9: 11.495938 | S9: -1.5895145 | T9: 4.206109 | U9: 3.7581065 | V9: 4.3429227
A10: 0.09 | B10: 5.8599195 | C10: 11.030143 | D10: -0.87099045 | E10: 9.5449073 | F10: 4.2073499 | G10: 7.6682973 | H10: 3.7946973 | I10: -1.9671264 | J10: -0.45193585 | K10: 0.65286334 | L10: 1.1112064 | M10: -1.2970756 | N10: 1.0600223 | O10: 5.6149918 | P10: 3.2826621 | Q10: 1.1192073 | R10: 11.030143 | S10: -1.9671264 | T10: 4.1876901 | U10: 3.4536344 | V10: 4.3075282
A11: 0.1 | B11: 5.3774256 | C11: 10.446191 | D11: -1.4236792 | E11: 8.7857411 | F11: 3.4636116 | G11: 7.6528991 | H11: 3.3268312 | I11: -2.26896 | J11: -0.055820291 | K11: 0.6626335 | L11: 0.74555152 | M11: -2.2905558 | N11: 0.19634201 | O11: 5.0535634 | P11: 2.8336982 | Q11: 1.1080105 | R11: 10.446191 | S11: -2.2905558 | T11: 4.1457956 | U11: 3.0365717 | V11: 4.2421337
A12: 0.11 | B12: 4.8872578 | C12: 9.9851722 | D12: -2.0650911 | E12: 7.9817933 | F12: 2.7154581 | G12: 7.6203789 | H12: 2.4290433 | I12: -2.51396 | J12: 0.2380826 | K12: 0.76254979 | L12: 0.163466 | M12: -3.2780333 | N12: -0.67799428 | O12: 4.1652667 | P12: 2.3152421 | Q12: 1.107917 | R12: 9.9851722 | S12: -3.2780333 | T12: 4.1454459 | U12: 2.5454911 | V12: 4.2205126
... A100: 0.99 | B100: -2.6445 | C100: 9.537535 | D100: 2.95667 | E100: 3.46649 | F100: 9.254723 | G100: 7.51487 | H100: -0.79961 | I100: 2.69903 | J100: -4.208457 | K100: -0.0568728 | L100: -4.314605 | M100: 5.75356 | N100: 1.90052 | O100: 8.2513745 | P100: 2.8079091 | Q100: 1.2828401 | R100: 9.537535 | S100: -4.314605 | T100: 4.7999482 | U100: 2.8777083 | V100: 4.9885439

Sheet 右股関節外転角度
A1: 0 | B1: -4.571 | C1: -1.55612 | D1: -0.888022 | E1: -0.607995 | F1: -1.200757 | G1: 3.347655 | H1: 4.28482 | I1: -0.296163 | J1: 1.8482365 | K1: 0.92451975 | L1: 0.88726 | M1: -4.73456 | N1: 0.443759 | O1: 6.022626 | P1: 0.27887566 | Q1: 0.80664801 | R1: 6.022626 | S1: -4.73456 | T1: 3.0182005 | U1: 0.26619233 | V1: 3.1410543
A2: 0.01 | B2: -4.7993507 | C2: -1.9895665 | D2: -0.93190133 | E2: -1.1430533 | F2: -1.6274146 | G2: 2.6945221 | H2: 3.563923 | I2: -0.424004 | J2: 1.6018034 | K2: 0.48503056 | L2: 0.11460404 | M2: -5.0879398 | N2: 0.15425491 | O2: 5.6044863 | P2: -0.12747186 | Q2: 0.78399258 | R2: 5.6044863 | S2: -5.0879398 | T2: 2.9334316 | U2: -0.14914315 | V2: 3.0520458
A3: 0.02 | B3: -4.9420577 | C3: -2.4367165 | D3: -0.98522228 | E3: -1.6947906 | F3: -2.0800328 | G3: 2.0535237 | H3: 2.8251103 | I3: -0.54211818 | J3: 1.3912829 | K3: -0.00049100101 | L3: -0.63888141 | M3: -5.4558601 | N3: -0.073285414 | O3: 5.0685775 | P3: -0.53649725 | Q3: 0.75882942 | R3: 5.0685775 | S3: -5.4558601 | T3: 2.8392797 | U3: -0.57212893 | V3: 2.9519563
A4: 0.03 | B4: -4.9814015 | C4: -2.9095847 | D4: -1.0541424 | E4: -2.2648209 | F4: -2.5639827 | G4: 1.4271706 | H4: 2.0530255 | I4: -0.64726327 | J4: 1.2339129 | K4: -0.53884485 | L4: -1.3398174 | M4: -5.8345112 | N4: -0.22277512 | O4: 4.4035028 | P4: -0.94568088 | Q4: 0.73130539 | R4: 4.4035028 | S4: -5.8345112 | T4: 2.7362942 | U4: -1.001289 | V4: 2.8397797
A5: 0.04 | B5: -5.0141662 | C5: -3.4018472 | D5: -1.1489136 | E5: -2.8187563 | F5: -3.0665289 | G5: 0.78458099 | H5: 1.2439632 | I5: -0.81832655 | J5: 1.1133892 | K5: -1.1580648 | L5: -2.0303861 | M5: -6.2153183 | N5: -0.34021973 | O5: 3.5811014 | P5: -1.3778209 | Q5: 0.70286718 | R5: 3.5811014 | S5: -6.2153183 | T5: 2.6298882 | U5: -1.4576364 | V5: 2.7195683
A6: 0.05 | B6: -5.0678772 | C6: -3.9004635 | D6: -1.2531651 | E6: -3.3709314 | F6: -3.5838503 | G6: 0.13116703 | H6: 0.41684445 | I6: -1.0389489 | J6: 0.98790368 | K6: -1.7725349 | L6: -2.7098445 | M6: -6.6082993 | N6: -0.49153274 | O6: 2.7649883 | P6: -1.8211817 | Q6: 0.68150041 | R6: 2.7649883 | S6: -6.6082993 | T6: 2.5499411 | U6: -1.9234624 | V6: 2.6240018
A7: 0.06 | B7: -5.1601406 | C7: -4.3655632 | D7: -1.3643761 | E7: -3.9218097 | F7: -4.1240808 | G7: -0.53854836 | H7: -0.45224645 | I7: -1.3560031 | J7: 0.810384 | K7: -2.3763213 | L7: -3.3344098 | M7: -7.0112191 | N7: -0.72566266 | O7: 1.9672439 | P7: -2.2823395 | Q7: 0.66430731 | R7: 1.9672439 | S7: -7.0112191 | T7: 2.4856104 | U7: -2.4020839 | V7: 2.5447285
A8: 0.07 | B8: -5.2537014 | C8: -4.761589 | D8: -1.4995761 | E8: -4.4558819 | F8: -4.6763233 | G8: -1.2082107 | H8: -1.2976208 | I8: -1.7301627 | J8: 0.52083795 | K8: -2.8846539 | L8: -3.9414737 | M8: -7.4257039 | N8: -1.1490305 | O8: 1.2378728 | P8: -2.7518012 | Q8: 0.64828781 | R8: 1.2378728 | S8: -7.4257039 | T8: 2.4256709 | U8: -2.8750913 | V8: 2.4786413
A9: 0.08 | B9: -5.3498472 | C9: -5.0791787 | D9: -1.6579912 | E9: -4.9461693 | F9: -5.2093421 | G9: -1.8742685 | H9: -2.1074202 | I9: -2.1282564 | J9: 0.15781931 | K9: -3.3517994 | L9: -4.5061914 | M9: -7.8033358 | N9: -1.6585226 | O9: 0.52656517 | P9: -3.2134242 | Q9: 0.6297269 | R9: 0.52656517 | S9: -7.8033358 | T9: 2.3562223 | U9: -3.333032 | V9: 2.407791
A10: 0.09 | B10: -5.4523118 | C10: -5.2770873 | D10: -1.9159518 | E10: -5.3691355 | F10: -5.6815496 | G10: -2.5303945 | H10: -2.8773064 | I10: -2.5329009 | J10: -0.37106487 | K10: -3.7475309 | L10: -5.0381145 | M10: -8.1482382 | N10: -2.2716205 | O10: -0.16696592 | P10: -3.6700123 | Q10: 0.60233772 | R10: -0.16696592 | S10: -8.1482382 | T10: 2.2537414 | U10: -3.7775809 | V10: 2.3080589
A11: 0.1 | B11: -5.5896807 | C11: -5.3530064 | D11: -2.203728 | E11: -5.6792079 | F11: -6.0797873 | G11: -3.1402256 | H11: -3.6313009 | I11: -2.9352291 | J11: -0.90614413 | K11: -4.0967096 | L11: -5.5309995 | M11: -8.459618 | N11: -2.824502 | O11: -0.78655184 | P11: -4.0869065 | Q11: 0.57490659 | R11: -0.78655184 | S11: -8.459618 | T11: 2.1511035 | U11: -4.1840145 | V11: 2.2067689
A12: 0.11 | B12: -5.7496278 | C12: -5.38403 | D12: -2.5390678 | E12: -5.9560811 | F12: -6.4383647 | G12: -3.7123883 | H12: -4.36201 | I12: -3.33582 | J12: -1.4498012 | K12: -4.414373 | L12: -5.8991356 | M12: -8.7233978 | N12: -3.3293272 | O12: -1.3649098 | P12: -4.4755953 | Q12: 0.54650283 | R12: -1.3649098 | S12: -8.7233978 | T12: 2.0448264 | U12: -4.5637698 | V12: 2.1004383
... A100: 0.99 | B100: -3.96042 | C100: -1.5548 | D100: -0.760229 | E100: -0.642403 | F100: -0.6061798 | G100: 3.54834 | H100: 3.80177 | I100: -2.08544 | J100: 1.513222 | K100: 1.9145977 | L100: 1.4996595 | M100: -2.58626 | N100: 0.799265 | O100: 6.392729 | P100: 0.51956082 | Q100: 0.75401304 | R100: 6.392729 | S100: -3.96042 | T100: 2.8212585 | U100: 0.49804511 | V100: 2.9352632

Sheet 左股関節外転角度
A1: 0 | B1: -4.16631 | C1: -3.341505 | D1: 2.3963 | E1: -3.6336 | F1: -3.831908 | G1: 1.86756 | H1: 1.22062 | I1: 2.10013 | J1: 2.34529 | K1: -1.382104 | L1: -3.945485 | M1: 3.282065 | N1: -0.989926 | O1: -0.061951625 | P1: -0.58148747 | Q1: 0.74693608 | R1: 3.282065 | S1: -4.16631 | T1: 2.7947789 | U1: -0.55006912 | V1: 2.9063236
A2: 0.01 | B2: -4.6353867 | C2: -3.8237181 | D2: 2.1947104 | E2: -4.3597598 | F2: -4.1058995 | G2: 1.1579791 | H2: 0.38893212 | I2: 1.6007436 | J2: 2.0393894 | K2: -2.0244406 | L2: -4.4233991 | M2: 3.0345717 | N2: -1.2119031 | O2: -0.51415364 | P2: -1.0487382 | Q2: 0.75670104 | R2: 3.0345717 | S2: -4.6353867 | T2: 2.831316 | U2: -1.036187 | V2: 2.9465218
A3: 0.02 | B3: -5.1066846 | C3: -4.3418673 | D3: 1.9956183 | E3: -5.0638625 | F3: -4.380744 | G3: 0.3876241 | H3: -0.44954152 | I3: 1.0471271 | J3: 1.7896362 | K3: -2.6972796 | L3: -4.8944721 | M3: 2.7963555 | N3: -1.4037388 | O3: -0.97292933 | P3: -1.5210542 | Q3: 0.77024021 | R3: 2.7963555 | S3: -5.1066846 | T3: 2.881975 | U3: -1.5300785 | V3: 2.9994488
A4: 0.03 | B4: -5.581847 | C4: -4.9036135 | D4: 1.8006524 | E4: -5.7391988 | F4: -4.6560878 | G4: -0.45607885 | H4: -1.3006173 | I4: 0.42120364 | J4: 1.6147463 | K4: -3.4035728 | L4: -5.3490456 | M4: 2.5516114 | N4: -1.5568332 | O4: -1.4394062 | P4: -1.9998634 | Q4: 0.78781017 | R4: 2.5516114 | S4: -5.7391988 | T4: 2.9477157 | U4: -2.0339426 | V4: 3.0652079
A5: 0.04 | B5: -6.0497148 | C5: -5.523592 | D5: 1.6015512 | E5: -6.2789846 | F5: -4.9586062 | G5: -1.2854757 | H5: -2.1843915 | I5: -0.27330855 | J5: 1.4818695 | K5: -4.0453385 | L5: -5.8068526 | M5: 2.2475418 | N5: -1.7470451 | O5: -1.9409092 | P5: -2.4830897 | Q5: 0.80526056 | R5: 2.2475418 | S5: -6.2789846 | T5: 3.0130091 | U5: -2.5397086 | V5: 3.128278
A6: 0.05 | B6: -6.5013548 | C6: -6.1285698 | D6: 1.4017948 | E6: -6.7275753 | F6: -5.2823924 | G6: -2.1002445 | H6: -3.0828088 | I6: -0.95083873 | J6: 1.3341419 | K6: -4.6447641 | L6: -6.266942 | M6: 1.8521148 | N6: -1.9901495 | O6: -2.4430256 | P6: -2.9664724 | Q6: 0.82062389 | R6: 1.8521148 | S6: -6.7275753 | T6: 3.0704934 | U6: -3.0415742 | V6: 3.1824592
A7: 0.06 | B7: -6.9169608 | C7: -6.6305918 | D7: 1.2066318 | E7: -7.0625603 | F7: -5.6380478 | G7: -2.8915755 | H7: -3.9931845 | I7: -1.5573353 | J7: 1.1317821 | K7: -5.1923661 | L7: -6.7988821 | M7: 1.4012999 | N7: -2.3201094 | O7: -2.9495662 | P7: -3.4436761 | Q7: 0.83255409 | R7: 1.4012999 | S7: -7.0625603 | T7: 3.1151322 | U7: -3.5301044 | V7: 3.2248142
A8: 0.07 | B8: -7.2483913 | C8: -6.9802252 | D8: 1.0268163 | E8: -7.2854624 | F8: -5.9738552 | G8: -3.6703003 | H8: -4.8298391 | I8: -2.0260473 | J8: 0.8302165 | K8: -5.6998499 | L8: -7.3555634 | M8: 0.89797264 | N8: -2.7682151 | O8: -3.45602 | P8: -3.895626 | Q8: 0.83606213 | R8: 1.0268163 | S8: -7.3555634 | T8: 3.128258 | U8: -3.9823499 | V8: 3.23843
A9: 0.08 | B9: -7.5298056 | C9: -7.2042569 | D9: 0.86185319 | E9: -7.4817328 | F9: -6.2793756 | G9: -4.4190277 | H9: -5.5559118 | I9: -2.42532 | J9: 0.4781384 | K9: -6.171738 | L9: -7.9836654 | M9: 0.37077247 | N9: -3.2613351 | O9: -3.9602027 | P9: -4.3258291 | Q9: 0.83719443 | R9: 0.86185319 | S9: -7.9836654 | T9: 3.1324947 | U9: -4.4077133 | V9: 3.2447713
A10: 0.09 | B10: -7.73257 | C10: -7.2931136 | D10: 0.71795173 | E10: -7.6501 | F10: -6.5237089 | G10: -5.0928636 | H10: -6.1030255 | I10: -2.73864 | J10: 0.0610791 | K10: -6.5932006 | L10: -8.5628359 | M10: -0.19929077 | N10: -3.8091214 | O10: -4.463774 | P10: -4.7130867 | Q10: 0.83056553 | R10: 0.71795173 | S10: -8.5628359 | T10: 3.1076917 | U10: -4.7826225 | V10: 3.2232321
A11: 0.1 | B11: -7.8857139 | C11: -7.2888406 | D11: 0.57912973 | E11: -7.833152 | F11: -6.6965361 | G11: -5.6826869 | H11: -6.57548 | I11: -3.0486982 | J11: -0.36491922 | K11: -6.9131726 | L11: -9.085826 | M11: -0.80375762 | N11: -4.3711202 | O11: -4.9860202 | P11: -5.0683424 | Q11: 0.81917444 | R11: 0.57912973 | S11: -9.085826 | T11: 3.0650701 | U11: -5.1219749 | V11: 3.1833813
A12: 0.11 | B12: -8.0087306 | C12: -7.2473828 | D12: 0.446915 | E12: -8.0172628 | F12: -6.8331598 | G12: -6.2234022 | H12: -6.91288 | I12: -3.35631 | J12: -0.7976218 | K12: -7.1829191 | L12: -9.3653183 | M12: -1.4394432 | N12: -4.9361544 | O12: -5.5066177 | P12: -5.3843063 | Q12: 0.79988223 | R12: 0.446915 | S12: -9.3653183 | T12: 2.9928853 | U12: -5.4187795 | V12: 3.1121994
... A100: 0.99 | B100: -4.348875 | C100: -3.433385 | D100: 3.16974 | E100: -2.95898 | F100: -3.6564055 | G100: 1.28763 | H100: 1.07119 | I100: 0.621485 | J100: 1.012117 | K100: -3.58868 | L100: -3.142525 | M100: 2.796585 | N100: -0.839317 | O100: -0.37152852 | P100: -0.8843535 | Q100: 0.69360244 | R100: 3.16974 | S100: -4.348875 | T100: 2.5952227 | U100: -0.88781785 | V100: 2.7011597

Sheet 右大腿上下動
A1: 0 | B1: 0.862795 | C1: 0.8677195 | D1: 0.905579 | E1: 0.867786 | F1: 1.019546 | G1: 0.972479 | H1: 0.971877 | I1: 0.941819 | J1: 0.88207575 | K1: 0.84707125 | L1: 0.8090465 | M1: 0.923631 | N1: 0.9632265 | O1: 0.9740115 | P1: 0.9149045 | Q1: 0.016286188 | R1: 1.019546 | S1: 0.8090465 | T1: 0.060937334 | U1: 0.91118742 | V1: 0.061751539
A2: 0.01 | B2: 0.862603 | C2: 0.8671723 | D2: 0.90404476 | E2: 0.86577494 | F2: 1.0195551 | G2: 0.97280805 | H2: 0.97209882 | I2: 0.94159691 | J2: 0.88198353 | K2: 0.84717967 | L2: 0.80855075 | M2: 0.92326262 | N2: 0.96222148 | O2: 0.97367954 | P2: 0.91446653 | Q2: 0.016337079 | R2: 1.0195551 | S2: 0.80855075 | T2: 0.061127753 | U2: 0.91079307 | V2: 0.061994535
A3: 0.02 | B3: 0.86274201 | C3: 0.86689743 | D3: 0.9026894 | E3: 0.86411427 | F3: 1.0197823 | G3: 0.97349828 | H3: 0.97249309 | I3: 0.94160636 | J3: 0.88205983 | K3: 0.84755389 | L3: 0.8083857 | M3: 0.92321188 | N3: 0.96188758 | O3: 0.97395092 | P3: 0.91434807 | Q3: 0.016397565 | R3: 1.0197823 | S3: 0.8083857 | T3: 0.061354071 | U3: 0.91069119 | V3: 0.062251061
A4: 0.03 | B4: 0.86328052 | C4: 0.86699965 | D4: 0.90162961 | E4: 0.86283791 | F4: 1.020273 | G4: 0.97462442 | H4: 0.97320764 | I4: 0.94192455 | J4: 0.88238551 | K4: 0.84825061 | L4: 0.80899555 | M4: 0.9234663 | N4: 0.96240162 | O4: 0.97488403 | P4: 0.91465435 | Q4: 0.016456448 | R4: 1.020273 | S4: 0.80899555 | T4: 0.061574391 | U4: 0.91098148 | V4: 0.062472062
A5: 0.04 | B5: 0.86400884 | C5: 0.86758934 | D5: 0.9010154 | E5: 0.8622974 | F5: 1.0210232 | G5: 0.97641288 | H5: 0.97434345 | I5: 0.94265564 | J5: 0.88301198 | K5: 0.84949476 | L5: 0.81004301 | M5: 0.92410974 | N5: 0.96378234 | O5: 0.97671057 | P5: 0.91546418 | Q5: 0.016528025 | R5: 1.0210232 | S5: 0.81004301 | T5: 0.061842208 | U5: 0.9117474 | V5: 0.062718771
A6: 0.05 | B6: 0.8647496 | C6: 0.86840289 | D6: 0.90060881 | E6: 0.86214265 | F6: 1.0218941 | G6: 0.97839263 | H6: 0.97568442 | I6: 0.94360791 | J6: 0.88375934 | K6: 0.85094638 | L6: 0.81138726 | M6: 0.92514344 | N6: 0.96529291 | O6: 0.97868926 | P6: 0.91647869 | Q6: 0.016594023 | R6: 1.0218941 | S6: 0.81138726 | T6: 0.062089148 | U6: 0.91272375 | V6: 0.062948184
A7: 0.06 | B7: 0.86547752 | C7: 0.86944727 | D7: 0.90061497 | E7: 0.86245058 | F7: 1.0229323 | G7: 0.98059126 | H7: 0.97749291 | I7: 0.94494109 | J7: 0.88469025 | K7: 0.8526927 | L7: 0.81293565 | M7: 0.92646306 | N7: 0.96683209 | O7: 0.98081187 | P7: 0.91774097 | Q7: 0.016659376 | R7: 1.0229323 | S7: 0.81293565 | T7: 0.062333676 | U7: 0.91396473 | V7: 0.063190199
A8: 0.07 | B8: 0.86637562 | C8: 0.87070787 | D8: 0.90083187 | E8: 0.86345935 | F8: 1.0242038 | G8: 0.98283374 | H8: 0.97940976 | I8: 0.94661791 | J8: 0.88567677 | K8: 0.85462463 | L8: 0.81454284 | M8: 0.92809074 | N8: 0.96814113 | O8: 0.98295647 | P8: 0.9191766 | Q8: 0.016710919 | R8: 1.0242038 | S8: 0.81454284 | T8: 0.062526534 | U8: 0.9154101 | V8: 0.063405065
A9: 0.08 | B9: 0.86741465 | C9: 0.87203027 | D9: 0.90125271 | E9: 0.86480228 | F9: 1.0255733 | G9: 0.98511932 | H9: 0.98148915 | I9: 0.94847036 | J9: 0.88670026 | K9: 0.85666254 | L9: 0.8163376 | M9: 0.9299574 | N9: 0.96938757 | O9: 0.98520053 | P9: 0.92074271 | Q9: 0.016754589 | R9: 1.0255733 | S9: 0.8163376 | T9: 0.062689933 | U9: 0.9170008 | V9: 0.063601633
A10: 0.09 | B10: 0.86873473 | C10: 0.87347668 | D10: 0.90202373 | E10: 0.86656582 | F10: 1.0270654 | G10: 0.98749605 | H10: 0.98381673 | I10: 0.95055191 | J10: 0.88783577 | K10: 0.8588541 | L10: 0.81823882 | M10: 0.93198573 | N10: 0.97066695 | O10: 0.98760015 | P10: 0.92249375 | Q10: 0.016791844 | R10: 1.0270654 | S10: 0.81823882 | T10: 0.062829329 | U10: 0.91878812 | V10: 0.063782605
A11: 0.1 | B11: 0.87048554 | C11: 0.87501854 | D11: 0.90294891 | E11: 0.86904208 | F11: 1.0286912 | G11: 0.98992388 | H11: 0.98625412 | I11: 0.952824 | J11: 0.8890356 | K11: 0.86116384 | L11: 0.82026735 | M11: 0.93417496 | N11: 0.97204436 | O11: 0.99021963 | P11: 0.92443529 | Q11: 0.016815849 | R11: 1.0286912 | S11: 0.82026735 | T11: 0.062919145 | U11: 0.92077305 | V11: 0.063916394
A12: 0.11 | B12: 0.87247056 | C12: 0.87661111 | D12: 0.90418 | E12: 0.87186444 | F12: 1.0303981 | G12: 0.99235667 | H12: 0.98893533 | I12: 0.955239 | J12: 0.89032448 | K12: 0.86355614 | L12: 0.82213517 | M12: 0.93659456 | N12: 0.97348894 | O12: 0.99300414 | P12: 0.92651133 | Q12: 0.016844898 | R12: 1.0303981 | S12: 0.82213517 | T12: 0.063027835 | U12: 0.92289767 | V12: 0.064074141
... A100: 0.99 | B100: 0.863215 | C100: 0.8680335 | D100: 0.902525 | E100: 0.867633 | F100: 1.0203 | G100: 0.9753055 | H100: 0.971726 | I100: 0.944866 | J100: 0.88186005 | K100: 0.84632735 | L100: 0.810378 | M100: 0.923467 | N100: 0.964374 | O100: 0.9764969 | P100: 0.91546481 | Q100: 0.016436647 | R100: 1.0203 | S100: 0.810378 | T100: 0.061500303 | U100: 0.91170256 | V100: 0.062312129

Sheet 左大腿上下動
A1: 0 | B1: 0.8549035 | C1: 0.870571 | D1: 0.900365 | E1: 0.868685 | F1: 1.0186095 | G1: 0.973169 | H1: 0.969936 | I1: 0.939652 | J1: 0.87595 | K1: 0.8504418 | L1: 0.81295 | M1: 0.927618 | N1: 0.974161 | O1: 0.98447025 | P1: 0.91582015 | Q1: 0.016619834 | R1: 1.0186095 | S1: 0.81295 | T1: 0.062185725 | U1: 0.91133239 | V1: 0.062320651
A2: 0.01 | B2: 0.85434188 | C2: 0.87115204 | D2: 0.89932985 | E2: 0.86695285 | F2: 1.0180955 | G2: 0.97328213 | H2: 0.96975358 | I2: 0.93938473 | J2: 0.87508537 | K2: 0.85170392 | L2: 0.81252555 | M2: 0.92740861 | N2: 0.97369506 | O2: 0.98368787 | P2: 0.91545707 | Q2: 0.016606129 | R2: 1.0180955 | S2: 0.81252555 | T2: 0.062134447 | U2: 0.91097722 | V2: 0.062273859
A3: 0.02 | B3: 0.8541343 | C3: 0.87183264 | D3: 0.89844408 | E3: 0.86559618 | F3: 1.0178739 | G3: 0.97360734 | H3: 0.96977564 | I3: 0.939685 | J3: 0.87463526 | K3: 0.85325499 | L3: 0.81238116 | M3: 0.92745803 | N3: 0.97369564 | O3: 0.98342218 | P3: 0.91541403 | Q3: 0.01660174 | R3: 1.0178739 | S3: 0.81238116 | T3: 0.062118024 | U3: 0.91093083 | V3: 0.062252444
A4: 0.03 | B4: 0.85438045 | C4: 0.87263871 | D4: 0.89780512 | E4: 0.86467402 | F4: 1.0179839 | G4: 0.97418852 | H4: 0.97017745 | I4: 0.940742 | J4: 0.87473785 | K4: 0.85512298 | L4: 0.81291224 | M4: 0.92774936 | N4: 0.97427471 | O4: 0.98367511 | P4: 0.91579017 | Q4: 0.01659563 | R4: 1.0179839 | S4: 0.81291224 | T4: 0.06209516 | U4: 0.91129136 | V4: 0.06221064
A5: 0.04 | B5: 0.8552839 | C5: 0.87362283 | D5: 0.89748119 | E5: 0.86435528 | F5: 1.0188161 | G5: 0.97513351 | H5: 0.97111085 | I5: 0.94253155 | J5: 0.87544059 | K5: 0.85733536 | L5: 0.81371069 | M5: 0.92832948 | N5: 0.97533339 | O5: 0.98476215 | P5: 0.91666049 | Q5: 0.016615522 | R5: 1.0188161 | S5: 0.81371069 | T5: 0.062169589 | U5: 0.91214719 | V5: 0.062275219
A6: 0.05 | B6: 0.85643865 | C6: 0.87468016 | D6: 0.89731203 | E6: 0.86427787 | F6: 1.0199392 | G6: 0.97628294 | H6: 0.97230127 | I6: 0.94450773 | J6: 0.8763128 | K6: 0.85973882 | L6: 0.81469786 | M6: 0.92920161 | N6: 0.97645199 | O6: 0.98615609 | P6: 0.91773565 | Q6: 0.016642685 | R6: 1.0199392 | S6: 0.81469786 | T6: 0.062271224 | U6: 0.91321901 | V6: 0.062381461
A7: 0.06 | B7: 0.85792158 | C7: 0.87580889 | D7: 0.89748764 | E7: 0.86449285 | F7: 1.0214225 | G7: 0.97772973 | H7: 0.97404673 | I7: 0.94664527 | J7: 0.8773586 | K7: 0.86237277 | L7: 0.81573861 | M7: 0.93029064 | N7: 0.97752879 | O7: 0.98788197 | P7: 0.9190519 | Q7: 0.016684723 | R7: 1.0214225 | S7: 0.81573861 | T7: 0.062428517 | U7: 0.91455367 | V7: 0.062571671
A8: 0.07 | B8: 0.85965459 | C8: 0.87693175 | D8: 0.89793379 | E8: 0.86510258 | F8: 1.023148 | G8: 0.97950217 | H8: 0.97594709 | I8: 0.94884055 | J8: 0.87845904 | K8: 0.86533449 | L8: 0.81679681 | M8: 0.93161567 | N8: 0.97846106 | O8: 0.9899974 | P8: 0.92055178 | Q8: 0.016731856 | R8: 1.023148 | S8: 0.81679681 | T8: 0.062604873 | U8: 0.91609722 | V8: 0.062809479
A9: 0.08 | B9: 0.86153581 | C9: 0.87802657 | D9: 0.89864176 | E9: 0.86592595 | F9: 1.0249413 | G9: 0.98138892 | H9: 0.97807982 | I9: 0.95109118 | J9: 0.87961605 | K9: 0.86832371 | L9: 0.81790349 | M9: 0.93311405 | N9: 0.97932385 | O9: 0.99230821 | P9: 0.92215862 | Q9: 0.016782505 | R9: 1.0249413 | S9: 0.81790349 | T9: 0.062794382 | U9: 0.91776129 | V9: 0.063075028
A10: 0.09 | B10: 0.86369591 | C10: 0.87910073 | D10: 0.89993991 | E10: 0.86706614 | F10: 1.026787 | G10: 0.98338391 | H10: 0.98058255 | I10: 0.95353545 | J10: 0.88098136 | K10: 0.8713036 | L10: 0.81906023 | M10: 0.93476332 | N10: 0.98015995 | O10: 0.99478162 | P10: 0.92393869 | Q10: 0.016831103 | R10: 1.026787 | S10: 0.81906023 | T10: 0.062976222 | U10: 0.91961397 | V10: 0.063346986
A11: 0.1 | B11: 0.86601168 | C11: 0.88018816 | D11: 0.9014542 | E11: 0.86859044 | F11: 1.0287367 | G11: 0.98549785 | H11: 0.98324733 | I11: 0.95599682 | J11: 0.88250985 | K11: 0.87422839 | L11: 0.82027442 | M11: 0.93654498 | N11: 0.98118939 | O11: 0.99742542 | P11: 0.92584969 | Q11: 0.016882838 | R11: 1.0287367 | S11: 0.82027442 | T11: 0.063169794 | U11: 0.92159279 | V11: 0.063624837
A12: 0.11 | B12: 0.86840189 | C12: 0.88134972 | D12: 0.90336122 | E12: 0.87034011 | F12: 1.0307258 | G12: 0.98768356 | H12: 0.98626067 | I12: 0.958471 | J12: 0.8841607 | K12: 0.8771392 | L12: 0.82153972 | M12: 0.9384885 | N12: 0.98234467 | O12: 1.0002395 | P12: 0.9278933 | Q12: 0.016939071 | R12: 1.0307258 | S12: 0.82153972 | T12: 0.063380198 | U12: 0.92370473 | V12: 0.063919624
... A100: 0.99 | B100: 0.8562725 | C100: 0.8717405 | D100: 0.90003 | E100: 0.8677885 | F100: 1.0182555 | G100: 0.976755 | H100: 0.971688 | I100: 0.94192 | J100: 0.8745481 | K100: 0.8581534 | L100: 0.811117 | M100: 0.926602 | N100: 0.9732405 | O100: 0.98237695 | P100: 0.91646342 | Q100: 0.016555389 | R100: 1.0182555 | S100: 0.811117 | T100: 0.061944595 | U100: 0.91209596 | V100: 0.062189977

Sheet 右重心上下動
A1: 0 | B1: 0.918186 | C1: 0.919919 | D1: 0.963834 | E1: 0.900565 | F1: 1.015376 | G1: 0.9858415 | H1: 0.971302 | I1: 1.00781 | J1: 0.89420995 | K1: 0.8457835 | L1: 0.849225 | M1: 0.940523 | N1: 1.046095 | O1: 0.9923534 | P1: 0.94650167 | Q1: 0.016405297 | R1: 1.046095 | S1: 0.8457835 | T1: 0.061383002 | U1: 0.93884064 | V1: 0.056495227
A2: 0.01 | B2: 0.91724798 | C2: 0.91920692 | D2: 0.962187 | E2: 0.89834909 | F2: 1.0148032 | G2: 0.98552182 | H2: 0.97081412 | I2: 1.0072182 | J2: 0.89400072 | K2: 0.84549398 | L2: 0.84825157 | M2: 0.93952957 | N2: 1.0449105 | O2: 0.99171285 | P2: 0.94566054 | Q2: 0.016409892 | R2: 1.0449105 | S2: 0.84549398 | T2: 0.061400193 | U2: 0.93802593 | V2: 0.056569645
A3: 0.02 | B3: 0.91650564 | C3: 0.91864897 | D3: 0.96068938 | E3: 0.89635551 | F3: 1.0143617 | G3: 0.985463 | H3: 0.9704567 | I3: 1.0067545 | J3: 0.89387709 | K3: 0.84549302 | L3: 0.84752312 | M3: 0.93873782 | N3: 1.0442538 | O3: 0.99147747 | P3: 0.9450427 | Q3: 0.01642437 | R3: 1.0442538 | S3: 0.84549302 | T3: 0.061454366 | U3: 0.93741107 | V3: 0.056639449
A4: 0.03 | B4: 0.91599945 | C4: 0.91830795 | D4: 0.95943858 | E4: 0.89460576 | F4: 1.0140785 | G4: 0.985719 | H4: 0.97034155 | I4: 1.0064618 | J4: 0.89388016 | K4: 0.84583965 | L4: 0.84736568 | M4: 0.93818291 | N4: 1.0442632 | O4: 0.99168645 | P4: 0.94472648 | Q4: 0.016443022 | R4: 1.0442632 | S4: 0.84583965 | T4: 0.061524156 | U4: 0.93706981 | V4: 0.056670251
A5: 0.04 | B5: 0.91578152 | C5: 0.91831593 | D5: 0.95858458 | E5: 0.89347037 | F5: 1.0141399 | G5: 0.98648411 | H5: 0.97054373 | I5: 1.0065073 | J5: 0.89404269 | K5: 0.84678168 | L5: 0.84754839 | M5: 0.93808321 | N5: 1.0449364 | O5: 0.99250423 | P5: 0.94483743 | Q5: 0.016470786 | R5: 1.0449364 | S5: 0.84678168 | T5: 0.061628038 | U5: 0.93713751 | V5: 0.05670364
A6: 0.05 | B6: 0.91569794 | C6: 0.91850851 | D6: 0.95791726 | E6: 0.89268771 | F6: 1.0144032 | G6: 0.98742456 | H6: 0.97090282 | I6: 1.0067418 | J6: 0.89427876 | K6: 0.84793819 | L6: 0.84796124 | M6: 0.93851726 | N6: 1.045701 | O6: 0.99344137 | P6: 0.94515155 | Q6: 0.016492192 | R6: 1.045701 | S6: 0.84793819 | T6: 0.061708134 | U6: 0.93741697 | V6: 0.056726476
A7: 0.06 | B7: 0.91580073 | C7: 0.91893811 | D7: 0.95762952 | E7: 0.89233185 | F7: 1.014963 | G7: 0.98858367 | H7: 0.97165918 | I7: 1.0073082 | J7: 0.89464773 | K7: 0.84939991 | L7: 0.84864776 | M7: 0.939315 | N7: 1.0464712 | O7: 0.99449733 | P7: 0.94572809 | Q7: 0.016505479 | R7: 1.0464712 | S7: 0.84864776 | T7: 0.061757849 | U7: 0.93797861 | V7: 0.056754244
A8: 0.07 | B8: 0.91619976 | C8: 0.91962051 | D8: 0.95756096 | E8: 0.89260532 | F8: 1.0158554 | G8: 0.98989563 | H8: 0.97257506 | I8: 1.0081882 | J8: 0.89507098 | K8: 0.85101188 | L8: 0.84941905 | M8: 0.94048167 | N8: 1.047014 | O8: 0.99561008 | P8: 0.94650774 | Q8: 0.016505909 | R8: 1.047014 | S8: 0.84941905 | T8: 0.061759456 | U8: 0.93877649 | V8: 0.056793817
A9: 0.08 | B9: 0.9167652 | C9: 0.9204171 | D9: 0.95770453 | E9: 0.89317487 | F9: 1.0168903 | G9: 0.99130571 | H9: 0.97373021 | I9: 1.0092336 | J9: 0.89553013 | K9: 0.85271686 | L9: 0.85047834 | M9: 0.94190505 | N9: 1.0474934 | O9: 0.99682358 | P9: 0.94744064 | Q9: 0.01649628 | R9: 1.0474934 | S9: 0.85047834 | T9: 0.061723427 | U9: 0.93974427 | V9: 0.05682323
A10: 0.09 | B10: 0.91760173 | C10: 0.92141986 | D10: 0.95821627 | E10: 0.89411573 | F10: 1.0181076 | G10: 0.99288955 | H10: 0.97525264 | I10: 1.0105191 | J10: 0.89608681 | K10: 0.85453837 | L10: 0.85167309 | M10: 0.94345109 | N10: 1.0480014 | O10: 0.99818904 | P10: 0.94857588 | Q10: 0.01648578 | R10: 1.0480014 | S10: 0.85167309 | T10: 0.06168414 | U10: 0.94092776 | V10: 0.056875805
